<?xml version="1.0"?>

<robot name="littlebot" xmlns:xacro="http://www.ros.org/wiki/xacro">

 <!--
########################################################################################
Modelagem do chassis2 "link" "joint" 
########################################################################################
-->
 <link name="base_link">
    <visual>
      <origin xyz="0 0 0" rpy="1.571 0 1.571" />
      <geometry>
	      <mesh filename="package://littlebot_description/meshes/chassis2.dae" />
      </geometry>
    </visual>
    <collision>
      <origin xyz="0 0 0" rpy="1.571 0 1.571" />
      <geometry>
	      <mesh filename="package://littlebot_description/meshes/chassis2.dae" />
      </geometry>
    </collision>
    <inertial>
      <origin xyz="0 0 0.15" rpy="1.571 0 1.571"/>
      <mass value="0.058"/>
      <inertia ixx="1.429e-4"  ixy="2.778e-10"  ixz="1.773e-8" iyy="1.943e-4" iyz="-2.656e-7" izz="5.361e-5" />
    </inertial>
  </link>  


<!--
########################################################################################
Modelagem da roda esquerda "link" "joint" 
########################################################################################
-->
  <link name="roda_esquerda"> 
    <visual>
      <origin xyz="0 -0.0115 0" rpy="0 0 1.571" />
      <geometry>
	      <mesh filename="package://littlebot_description/meshes/roda.dae" />
      </geometry>
    </visual>
    <collision>
      <origin xyz="0 -0.0115 0" rpy="0 0 1.571" />
      <geometry>
	      <mesh filename="package://littlebot_description/meshes/roda.dae" />
      </geometry>
    </collision>
    <inertial>
      <origin xyz="0 -0.0115 0" rpy="0 0 1.571"/>
      <mass value="0.041"/>
      <inertia ixx="2.967e-5"  ixy="-7.675e-15"  ixz="-4.765e-14" iyy="1.616e-5" iyz="-1.121e-16" izz="1.616e-5" />
    </inertial>
  </link>

  <joint name="base_to_roda_esquerda" type="continuous">
    <parent link="base_link"/>
    <child link="roda_esquerda"/>
    <origin xyz="0.005 0.07393 -0.014" rpy="0 0 0" />
    <axis xyz="0 1 0" />
  </joint>

  <gazebo reference="roda_esquerda">
    <mu1 value="1.0"/>
    <mu2 value="1.0"/>
    <kp  value="10000000.0" />
    <kd  value="1.0" />
    <fdir1 value="1 0 0"/>
    <turnGravityOff>false</turnGravityOff>
  </gazebo>



<!--
########################################################################################
Modelagem da roda direita "link" "joint"
########################################################################################
-->
  <link name="roda_direita">   
    <visual>
      <origin xyz="0 0.0115 0" rpy="0 0 -1.571" />
      <geometry>
	      <mesh filename="package://littlebot_description/meshes/roda.dae" />
      </geometry>
    </visual>
    <collision>
      <origin xyz="0 0.0115 0" rpy="0 0 -1.571 " />
      <geometry>
	      <mesh filename="package://littlebot_description/meshes/roda.dae" />
      </geometry>
    </collision>
    <inertial>
      <origin xyz="0 0.0115 0" rpy="0 0 -1.571"/>
      <mass value="0.041"/>
      <inertia ixx="2.967e-5"  ixy="-7.675e-15"  ixz="-4.765e-14" iyy="1.616e-5" iyz="-1.121e-16" izz="1.616e-5" />
    </inertial>
  </link>

  <joint name="base_to_roda_direita" type="continuous">
    <parent link="base_link"/>
    <child link="roda_direita"/>
    <origin xyz="0.005 -0.07393 -0.014" rpy="0 0 0" />
    <axis xyz="0 1 0" />
  </joint>

  <gazebo reference="roda_direita">
    <mu1 value="1.0"/>
    <mu2 value="1.0"/>
    <kp  value="10000000.0" />
    <kd  value="1.0" />
    <fdir1 value="1 0 0"/>
    <turnGravityOff>false</turnGravityOff>
  </gazebo>



<!--
########################################################################################
Modelagem da rodinha "link" "joint"
######################################################################################## -->
  <link name="rodinha">                                                                                                                                         
    <visual>                                                                    
      <!--<origin xyz="0 0 0" rpy="3.14 0 1.571" /> -->
      <origin xyz="0 0 0" rpy="3.14 0 2.141" />                                                   
      <geometry>                                                                   
	      <mesh filename="package://littlebot_description/meshes/Caster_Wheel.dae" />     
      </geometry>                                                                   
    </visual>                                                                   
    <collision>                                                                   
      <origin xyz="0 0 0" rpy="3.14 0 2.141" />                                                    
      <geometry>                                                                   
	      <mesh filename="package://littlebot_description/meshes/Caster_Wheel.dae" />     
      </geometry>                                                                   
    </collision>                                                                    
    <inertial>                                                                    
      <origin xyz="0 0 0" rpy="3.14 0 2.141"/>                                                                   
      <mass value="0.073"/>                                                                   
      <inertia ixx="5.470e-6"  ixy="4.042e-7"  ixz="3.515e-7" iyy="7.169e-6" iyz="-3.645e-7" izz="7.383e-6" />                                                                   
    </inertial>                                                                   
  </link>                                                                   

  <joint name="base_to_rodinha" type="fixed">
    <parent link="base_link"/>
    <child link="rodinha"/>
    <origin xyz="-0.07 0.0 -0.003" rpy="0 0 0" />
  </joint>


<!--
########################################################################################
Modelagem do motor esquerdo "link" "joint"
########################################################################################
-->
  <link name="motor_esquerdo">                                                                                                                                         
    <visual>                                                                    
      <origin xyz="0 0 0" rpy="0 0 0" />                                                   
      <geometry>                                                                   
	      <mesh filename="package://littlebot_description/meshes/motor.dae" />     
      </geometry>                                                                   
    </visual>                                                                   
    <collision>                                                                   
      <origin xyz="0 0 0" rpy="0 0 0" />                                                    
      <geometry>                                                                   
	      <mesh filename="package://littlebot_description/meshes/motor.dae" />     
      </geometry>                                                                   
    </collision>                                                                    
    <inertial>                                                                    
      <origin xyz="0 0 0" rpy="0 0 0"/>                                                                   
      <mass value="0.09"/>                                                                   
      <inertia ixx="0"  ixy="0"  ixz="0" iyy="0" iyz="0" izz="0" />                                                                   
    </inertial>                                                                   
  </link>                                                                   

  <joint name="base_to_motor_esquerdo" type="fixed">
    <parent link="base_link"/>
    <child link="motor_esquerdo"/>
    <origin xyz="-0.032 0.0387 -0.014" rpy="0 0 0" />
  </joint>
  

<!--
########################################################################################
Modelagem do motor direito "link" "joint"
########################################################################################
-->
  <link name="motor_direito">                                                                                                                                         
    <visual>                                                                    
      <origin xyz="0 0 0" rpy="0 0 0" />                                                   
      <geometry>                                                                   
	      <mesh filename="package://littlebot_description/meshes/motor.dae" />     
      </geometry>                                                                   
    </visual>                                                                   
    <collision>                                                                   
      <origin xyz="0 0 0" rpy="0 0 0" />                                                    
      <geometry>                                                                   
	      <mesh filename="package://littlebot_description/meshes/motor.dae" />     
      </geometry>                                                                   
    </collision>                                                                    
    <inertial>                                                                    
      <origin xyz="0 0 0" rpy="0 0 0"/>                                                                   
      <mass value="0.09"/>                                                                   
      <inertia ixx="0"  ixy="0"  ixz="0" iyy="0" iyz="0" izz="0" />                                                                   
    </inertial>                                                                   
  </link>                                                                   

  <joint name="base_to_motor_direito" type="fixed">
    <parent link="base_link"/>
    <child link="motor_direito"/>
    <origin xyz="-0.032 -0.0387 -0.014" rpy="0 0 0" />
  </joint>

<!--
********************************************************************************************
Transmission para as rodas
********************************************************************************************
-->
  <transmission name="trans_roda_esquerda" type="SimpleTransmission">
    <type>transmission_interface/SimpleTransmission</type>
    <joint name="base_to_roda_esquerda">
      <hardwareInterface>hardware_interface/VelocityJointInterface</hardwareInterface>
    </joint>
    <actuator name="roda_esquerda_motor">
      <mechanicalReduction>1</mechanicalReduction>
    </actuator>
  </transmission>


  <transmission name="trans_roda_direita">
    <type>transmission_interface/SimpleTransmission</type>
    <joint name="base_to_roda_direita">
      <hardwareInterface>hardware_interface/VelocityJointInterface</hardwareInterface>
    </joint>
    <actuator name="roda_direita_motor">
      <mechanicalReduction>1</mechanicalReduction>
    </actuator>
  </transmission>


  <!-- 
  ******************************************************************************************
  ros_control gazebo plugin 
  ******************************************************************************************
  -->
  <gazebo>
    <plugin name="gazebo_ros_control" filename="libgazebo_ros_control.so">
      <robotNamespace>/</robotNamespace>
    </plugin>
  </gazebo>

  <!-- 
  ******************************************************************************************
  IMU gazebo plugin 
  ******************************************************************************************
  -->
  <gazebo>
    <plugin name="imu_controller" filename="libhector_gazebo_ros_imu.so">
      <robotNamespace>/</robotNamespace>
      <updateRate>50.0</updateRate>
      <bodyName>base_link</bodyName>
      <topicName>imu/data</topicName>
      <accelDrift>0.005 0.005 0.005</accelDrift>
      <accelGaussianNoise>0.005 0.005 0.005</accelGaussianNoise>
      <rateDrift>0.005 0.005 0.005 </rateDrift>
      <rateGaussianNoise>0.005 0.005 0.005 </rateGaussianNoise>
      <headingDrift>0.005</headingDrift>
      <headingGaussianNoise>0.005</headingGaussianNoise>
    </plugin>
  </gazebo>
</robot>
