<?xml version="1.0"?>

<robot name="littlebot_wheel" xmlns:xacro="http://ros.org/wiki/xacro" >

<xacro:macro name="littlebot_wheel" params="lado_roda *mesh_pose *joint_roda_pose *joint_motor_pose">
<!--
########################################################################################
Modelagem da roda "link" "joint" "transmission" "gazebo"
########################################################################################
-->
	<link name="roda_${lado_roda}">
		<visual>
			<xacro:insert_block name="mesh_pose"/>
			<geometry>
				<mesh filename="package://littlebot_description/meshes/roda.dae" />
			</geometry>
		</visual>
		<collision>
			<xacro:insert_block name="mesh_pose"/>
			<geometry>
				<mesh filename="package://littlebot_description/meshes/roda.dae" />
			</geometry>
		</collision>
		<inertial>
			<xacro:insert_block name="mesh_pose"/>
			<mass value="0.041"/>
			<inertia ixx="2.967e-5"  ixy="-7.675e-15"  ixz="-4.765e-14" iyy="1.616e-5" iyz="-1.121e-16" izz="1.616e-5" />
		</inertial>
	</link>

	<joint name="base_to_roda_${lado_roda}" type="continuous">
		<parent link="chassis"/>
		<child link="roda_${lado_roda}"/>
		<xacro:insert_block name="joint_roda_pose"/>
		<axis xyz="1 0 0" rpy="0 0 0" />
	</joint>

	<transmission name="trans_roda_${lado_roda}">
		<type>transmission_interface/SimpleTransmission</type>
		<joint name="base_to_roda_${lado_roda}">
			<hardwareInterface>hardware_interface/VelocityJointInterface</hardwareInterface>
		</joint>
		<actuator name="roda_${lado_roda}_motor">
			<mechanicalReduction>1</mechanicalReduction>
		</actuator>
	</transmission>

	<gazebo reference="roda_${lado_roda}">
		<mu1 value="1000.0"/>
		<mu2 value="1.0"/>
		<kp value="10000000.0" />
		<kd value="1.0" />
		<fdir1 value="1 0 0"/>
	</gazebo>
<!--
########################################################################################
Modelagem da roda direita "link" "joint"
########################################################################################
-->
	<link name="motor_${lado_roda}">                                                                                                                                         
		<visual>                                                                    
			<origin xyz="0 0 0" rpy="0 0 0" />                                                   
			<geometry>                                                                   
				<mesh filename="package://littlebot_description/meshes/motor.dae" />     
			</geometry>                                                                   
		</visual>                                                                   
		<collision>                                                                   
			<origin xyz="0 0 0" rpy="0 0 0" />                                                    
			<geometry>                                                                   
				<mesh filename="package://littlebot_description/meshes/motor.dae" />     
			</geometry>                                                                   
		</collision>                                                                    
		<inertial>                                                                    
			<origin xyz="0 0 0" rpy="0 0 0"/>                                                                   
			<mass value="0.09"/>                                                                   
			<inertia ixx="0"  ixy="0"  ixz="0" iyy="0" iyz="0" izz="0" />                                                                   
		</inertial>                                                                   
	</link>                                                                   

	<joint name="base_to_motor_${lado_roda}" type="fixed">
		<parent link="chassis"/>
		<child link="motor_${lado_roda}"/>
		<xacro:insert_block name="joint_motor_pose"/>
	</joint>

</xacro:macro>

</robot>
